â†“ Module.hs:2
â†“ suite
â†“ sub suite
âœ— test 5
assertion error

â†“ Module.hs:2
â†“ suite
â†“ sub suite
âœ— test 6
Test threw an exception
Control.Exception.Safe.throwString called with:

exception
Called from:


â†“ Module.hs:2
â†“ suite
â†“ sub suite
âœ— test 7
Test timed out

â†“ Module.hs:2
â†“ suite
â†“ sub suite
âœ— test 7
Test runner encountered an unexpected error:
sorry
This is a bug.

If you have some time to report the bug it would be much appreciated!
You can do so here: https://github.com/NoRedInk/haskell-libraries/issues

[4mTEST RUN FAILED[m

Passed:    2
Skipped:   2
Failed:    4
